Когато програмирате, грешките се случват. Това е просто факт от живота. Може би потребителят е дал неправилни данни. Може би ресурс от мрежата не е бил достъпен. Може би програмата е изчерпала паметта. Или дори самият програмист може да е направил грешка!

Решението в Python за грешки са изключенията. Възможно е да сте виждали изключение преди.

    print(a)
    
    #грешка
    Traceback (most recent call last):
      File "<stdin>", line 1, in <module>
    NameError: name 'a' is not defined

О, забравили сте да присвоите стойност на променливата 'a'.

Но понякога не искате изключенията да спират програмата изцяло. Можете да искате да направите нещо специално, когато възникне изключение. Това се прави в блок *try/except*.

Ето един тривиален пример: Да предположим, че обхождате списък. Трябва да обхождате 20 числа, но списъкът е създаден от потребителски вход и може да няма 20 числа в него. След като достигнете края на списъка, просто искате останалите числа да бъдат интерпретирани като 0. Ето как бихте могли да го направите:

    def do_stuff_with_number(n):
        print(n)
    
    def catch_this():
        the_list = (1, 2, 3, 4, 5)
    
        for i in range(20):
            try:
                do_stuff_with_number(the_list[i])
            except IndexError: # Вдига се, когато се достъпва несъществуващ индекс на списък
                do_stuff_with_number(0)
    
    catch_this()

Ето, това не беше много трудно! Можете да го направите с което и да е изключение. За повече подробности относно обработката на изключения, вижте [Python Docs](http://docs.python.org/tutorial/errors.html#handling-exceptions)

Упражнение
--------

Обработете всички изключения! Спомнете си предишните уроци, за да върнете фамилията на актьора.